Workbook
Name PochodzenieVarant: Data_Validation!$B$33:$B$39
Name PochodzenieWyspyPołudniowe: Data_Validation!$B$48
Name PochodzenieArcholos: Data_Validation!$B$40:$B$44
Name PochodzenieWschodniArchipelag: Data_Validation!$B$49
Name Postać: Data_Validation!$B$3
Name PostaćNazwa: Postacie!$B$2:$B$50
Name PochodzenieKhorinis: Data_Validation!$B$22:$B$23
Name Klasa: Data_Validation!$B$1
Name Grupa: Data_Validation!$B$2:$C$2
Name PochodzenieNordmar: Data_Validation!$B$45:$B$47
Name GrupaNazwa: Grupy!$B$2:$B$100
Name PochodzenieMyrtana: Data_Validation!$B$24:$B$32
Name KlasaNazwa: Data_Validation!$A$5

Sheet Postacie
A1: L.p. | B1: Imię postaci | C1: Kontynuacja | D1: Pochodzenie ogólne | E1: Pochodzenie dokładne | F1: Grupa / Profesja | G1: Mechaniczne umiejętności | H1: Krótki opis postaci | I1: Najważniejsi znajomi | J1: Słowa kluczowe | K1: Wątki | L1: Najważniejsze fakty z podsumowania
A2: 1 | B2: Bezi | C2: TAK | D2: Khorinis | E2: Miasto Khorinis | F2: Łowcy | G2: Pozyskiwanie komponentów: - oko ścierwojada - jad umarlaka | H2: Kolejny ateista | I2: Diego, Milten, Gorn, Lester | J2: walka, polowania | K2: Ukradnij cebulę | L2: - Ledwo co go zrzucili, zbiera znajomości w każdym z obozów - Został pobity przez Bullita
A3: 2 | B3: Gor Na Rex | C3: TAK
A4: 3 | B4: Gor Na Ragu | C4: TAK | D4: Archolos | E4: Silbach | H4: Niedawno mianowany na Gor Na, wciąż pamięta dom sprzed wrzucenia pod barierę, ale powoli stawia Bractwo na właściwym miejscu. | I4: Maruda, Sztychu, Najemnicy | J4: pojedynek, walka z potworami, przesłuchanie, odurzenie
A5: 4 | B5: Gor Vikr | C5: TAK | D5: Khorinis | E5: Farmy | H5: Wierzący pragmatyk w Straży Świątynnej z kontaktami w NO | I5: Rickard, Inger, Baal Sachs, Orrin, Gor Na Rex | J5: walka, przesłuchania, odurzenie, wyłudzenie, hazard
A6: 5 | B6: Gor Han | C6: TAK
A7: 6 | B7: Gor Tar | C7: TAK
A8: 7 | B8: Gor Toth | C8: TAK
A9: 8 | B9: Gor Gyyrax | C9: NIE
A10: 9 | B10: Gor Balar | C10: NIE
A11: 10 | B11: Gor Ruh | C11: NIE
A12: 11 | B12: Gor Omba | C12: TAK
A13: 12 | B13: Gor Gior | C13: NIE
A14: 13 | B14: Gor Bács | C14: NIE | D14: Archolos | E14: Miasto Archolos | I14: Omba, Cefre, szkodnicy z Archolos | L14: Cienie, którzy go pobili jak był skazańcem: Torin(napierdalał), Daevon(odciągał Torina).
A15: 14 | B15: Gor Vith | C15: NIE

Sheet Grupy
A1: L.p. | B1: Nazwa grupy | C1: Członkowie (imiona postaci rozdzielone przecinkiem)
A2: 1 | B2: SS PL | C2: Gor Na Rex,Gor Na Ragu,Gor Vikr,Gor Tar,Gor Toth,Gor Gyyrax,Gor Balar,Gor Ruh,Gor Vith,Gor Han
A3: 2 | B3: SS EN | C3: Gor Omba,Gor Gior,Gor Bács
A4: 3 | B4: Gor Na | C4: Gor Na Rex,Gor Na Ragu
A5: 4 | B5: New Gor PL | C5: Gor Tar,Gor Gyyrax,Gor Balar,Gor Ruh,Gor Vith
A6: 5 | B6: New Gor EN | C6: Gor Gior,Gor Bács
A7: 6 | B7: Dodatkowy nowicjusz | C7: Gor Gyyrax,Gor Balar
A8: 7 | B8: Siatka szpiegowska | C8: Gor Toth,Gor Vikr
A9: 8 | B9: Zbieranie zasobów | C9: Gor Vith,Gor Ruh
A10: 9 | B10: SS Kont PL | C10: Gor Na Rex,Gor Na Ragu,Gor Vikr,Gor Han,Gor Tar,Gor Toth
A11: 10 | B11: SS Kont Gor PL | C11: Gor Vikr,Gor Toth,Gor Han
A12: 11 | B12: SS Kont Gor EN | C12: Gor Omba

Sheet Wątki
A1: Nazwa wątku | B1: Zakres wątku | C1: Wymień członków | D1: Nazwa klasy / grupy / postaci | E1: Kolejność | F1: Wpis fabularny | G1: Krótki opis | H1: Zleceniodawca | I1: Zaangażowane frakcje | J1: Potrzebne rekwizyty | K1: Nagroda
A2: Czarna Szychta | B2: Postać | C2: Nie | D2: Gor Vikr | E2: 33 | F2: Twoje kontakty w kolonii przynoszą efekty. Zeszłej nocy dostałeś informację, że pewien Strażnik Gomeza znany jako Szczerba prowadzi nocą w Starej Kopalni nielegalne wydobycie rudy. Cały zysk omija Gomeza i trafia przede wszystkim do tych, którzy to wydobycie organizują. Zawarłeś z nimi umowę: pomożesz w przedsięwzięciu chroniąc w nocy kopiących przed pełzaczami, a w zamian dostaniesz zapłatę. Ot prosta ruda. Dodatkowo Strażnik wspominał, że szukają dodatkowych kopaczy do tej roboty, więc jeśli przyprowadzisz ze sobą dwóch Nowicjuszy do kopania to możesz liczyć na lepszą zapłatę niż kwota za samą ochronę, a ponadto już wcześniej dałeś cynk Vik i Milo o dodatkowej robocie. Teraz tylko musisz sprawdzić ich zainteresowanie całą akcją i upewnić się, że nie upalą się zielem wieczorem jak będziecie mieli iść kopać. Jesteś umówiony ze Szczerbą na spotkanie pod kopalnią o 22. Jeśli się uda to wiesz, że masz szansę trochę się dorobić i tym samym umocnić swoja pozycję jak i przybliżyć się do awansu na Gor Na. W końcu to przedsiębiorczość Gor Na Groma sprawiła, że stał on tak wysoko pośród was. | G2: Czarnach szychta Vikr | H2: Chciwość | I2: Strażnicy Świątynni, Nowicjusze, Strażnicy, Kopacze | J2: narzędzia dla kopiących | K2: ruda
A3: Ziele poza naszą kontrolą | B3: Grupa | C3: Tak | D3: SS Kont PL | E3: 27 | F3: Parę dni temu, kiedy patrolowaliście ścieżki w okolicy Faktorii Bractwa minęliście grupę popalających bagienne ziele Cieni wracających do Starego Obozu. Niby normalny widok jak na co dzień, ale coś w tym było nie tak, coś wam w tym śmierdziało... Wszyscy jakby słysząc rozkaz zwolniliście krok i zaczęliście patrzeć po sobie szukając potwierdzenia o podejrzeniach jakie was ogarnęły... To bagienne ziele nie pachniało jak zwykły Zielony Nowicjusz. To musiało być coś więcej... Zawróciliście i zwracając się do Cieni zaczęliście wypytywać ich o źródło pochodzenia tego ziela i niestety, ale wiele się nie dowiedzieliście. Ot, że czasem takie skręty pojawiają się u przeróżnych handlarzy i nie ma ich dużo. Banda Cieni sama była zaskoczona jak się dowiedziała, że tego gatunku ziela Faktoria Bractwa nie sprzedaje byle komu... Finalnie doszliście do wniosku, że ktoś produkuje te skręty poza Faktorią Bractwa i sprzedaje z dużym zyskiem... To nie może dłużej trwać. Trzeba odnaleźć winowajców i odpowiednio ukarać. | G3: Akania ma przepis na wytworzenie mroku północy i robi z tego biznes. (To nie będzie mrok północy tylko eksperymentalne ziele Światło Poranka. Przepis pozostaje taki sam, tylko nazwa inna plus będzie zawinięte w niebieskie smakowe bletki, żeby SŚ łatwiej była w stanie prowadzić dochodzenie. Można wręczyć SŚ parę sztuk na początek larpa, zależy jak dużo pomocy potrzebują. - Joplin) | H3: Los | I3: Strażnicy Świątynni, Szkodniki | J3: Dostawca NPC dla Akanii Przepis (Domingo ogarnia) | K3: ruda
A4: Poprzednim razem w Faktorii Bractwa Śniącego | B4: Grupa | C4: Nie | D4: SS PL | E4: 20 | F4: Ostatatnie większe wydarzenie w Faktorii Bractwa polegało na zorganizowaniu i przeprowadzeniu obchodów Święta Pierwszego Słowa, co, jak się okazało, nie zostało przez władze Faktorii wykonane w stopniu zadowalającym dla Cor Kaloma. W konsekwencji Mistrz Orun został odwołany ze stanowiska zarządcy i odesłany z powrotem do obozu na bagnie. Na jego miejsce Y'Berion wysłał innych Guru, jednych z mniejszym, innych z większym doświadczeniem w kierowaniu wspólnotą. Wiesz że, oznacza to początek cichej walki o władze, względy i osiągnięcia. Jesteś tego pewny jak swojej wiary w Śniącego. | G4: Podsumowanie wydarzeń polityczno-społecznych z ostatniej edycji. | H4: Śniący | I4: Guru, Strażnicy Świątynni, Nowicjusze | J4: brak | K4: brak
A5: Trwająca wojna Straży Świątynnej z orkami | B5: Grupa | C5: Nie | D5: SS PL | E5: 21 | F5: Poprzedni konflikt zbrojny z orkami w okolicach Faktorii Bractwa Śniącego pokazały prawdziwą siłę Straży Świątynnej. Braciom udało się odeprzeć zagrożenie ze strony orków, niestety nie dość skutecznie. Szamanowi, który zaklinał magią leśne bestie udało się zbiec. Choć jego bestie zostały pokonane, a orkowa eskorta pobita i pogoniona to pewne jest, że po zalizaniu ran, będzie chciał wziąć odwet. Niestety nawet w samych szeregach Straży Świątynnej można dostrzec straty poniesione przez tamte wyczerpujące potyczki. Część Gor Na na wezwanie Cor Kaloma musiała wrócić, aby pomóc w ochronie Obozu Bractwa przed plagą węży błotnych, które poczuły się zbyt swobodnie i zaczęły wykluwać w zastraszającym tempie. Spora część Gor nie przeżyła walk z bestiami szamana oraz orkami. Wraz z nowymi Guru przybywającymi do Faktorii mają nadejść i nowi Gor, którzy będą konkurować ze sobą aby osiągnąć tytułu Gor Na. Tylko co musi się wydarzyć, żeby odwrócić fatum nowo rozwijającej się sytuacji w Faktorii Bractwa? | G5: Podsumowanie wydarzeń militarno-społecznych z ostatniej edycji. | H5: Śniący | I5: Guru, Strażnicy Świątynni, Nowicjusze | J5: brak | K5: brak
A6: Last time at Brotherhood of the Sleeper's Outpost | B6: Grupa | C6: Nie | D6: SS EN | E6: 20 | F6: The most recent major events at the Brotherhood Outpost involved organizing and carrying out the celebration of the Festival of the First Word — something the Outpost’s authorities failed to execute to Cor Kalom’s satisfaction. As a result, not only was Master Orun dismissed and sent back to the Swamp Camp, but new Gurus have now taken his place — some with less, others with more experience in leading our community. In your eyes, it seems as certain as the fact that the Sleeper is a god: a silent struggle for power, favor, and achievements is beginning. | G6: Podsumowanie wydarzeń polityczno-społecznych z ostatniej edycji. Wersja EN | H6: Śniący | I6: Guru, Strażnicy Świątynni, Nowicjusze | J6: brak | K6: brak
A7: The ongoing war between the Temple Guard and the orcs. | B7: Grupa | C7: Nie | D7: SS EN | E7: 21 | F7: The previous armed conflict with the orcs near the Brotherhood Outpost revealed the true strength of the Temple Guards. The brothers managed to repel the orc threat — unfortunately, not definitely. The shaman who had been controling forest beasts with magic managed to escape. Though his beasts were defeated and his orkish escort crushed and routed, it is certain that once he licks his wounds, he will seek revenge. Regrettably, even within the ranks of the Temple Guards, the toll of those exhausting skirmishes is evident. Some of the Gor Na had to return at Cor Kalom’s call to help defend the Swamp Camp against a plague of swampsharks, which had grown too bold and begun hatching at an alarming rate. A significant number of Gor perished in the battles against the shaman’s beasts and his orcs. New Gurus are expected to arrive to the Outpost — and with them Gors who will compete against each other for the title of Gor Na. But what must happen to break the curse hanging over the unfolding events at the Brotherhood Outpost? | G7: Podsumowanie wydarzeń militarno-społecznych z ostatniej edycji. Wersja EN | H7: Śniący | I7: Guru, Strażnicy Świątynni, Nowicjusze | J7: brak | K7: brak
A8: Czas próby | B8: Grupa | C8: Nie | D8: New Gor PL | E8: 22 | F8: Wczoraj wieczorem Cor Angar zebrał nas, początkujących Gor'ów, i zapowiedział, że w nadchodzących dniach okaże się, czy osiągnęliśmy poziom godny tytułu mistrzowskiego – Gor Na. Powiedział, że to właśnie w Faktorii Bractwa czeka na nas szereg ostatnich prób: zarówno zadań powierzonych przez Mistrzów, jak i wyzwań, które Kolonia Górnicza zdecyduje rzucić naszym braciom przebywającym na miejscu. To właściwy czas na rozwinięcie zdolności magicznych i łowieckich, a Mistrzowie z pewnością będą nas uważnie obserwować. Muszę umocnić swoją pozycję w Straży Świątynnej i tym samym zapewnić sobie awans... czuję się zdeterminowany dokonać tego za WSZELKĄ cenę. | G8: Wstęp fabularny dla nowych Gor'ów | H8: Cor Angar | I8: Strażnicy Świątynni | J8: brak | K8: brak
A9: Time of trials | B9: Grupa | C9: Nie | D9: New Gor EN | E9: 22 | F9: Last evening, Cor Angar gathered us — aspiring Gors — and announced that in the coming days it would be revealed whether we have reached the level worthy of the master title — Gor Na. He said that it is in the Brotherhood Outpost a series of final trials awaits us: either tasks entrusted to us by the Masters and challenges that the Velley of Mines may choose to throw at our brothers stationed there. It is high time to develop my magical and hunting skills, and the Masters will surely be watching us closely. I must solidify my position within the Temple Guards and by doing so ensure myself a promotion... I feel determined to do it by ALL possible means. | G9: Wstęp fabularny dla nowych Gor'ów | H9: Cor Angar | I9: Strażnicy Świątynni | J9: brak | K9: brak
A10: Dwa to lepiej niż jeden | B10: Grupa | C10: Nie | D10: Dodatkowy nowicjusz | E10: 24 | F10: Po odprawie Cor Angara otrzymałem poradę od Gor Na Rana, który powiedział mi, że biorąc pod uwagę liczbę Strażników Świątynnych w faktorii, Gor Na Kagan na pewno postawi przed nami zadanie znalezienia po kandydacie do Straży Świątynnej wśród Nowicjuszy. Powiedział mi, żebym nie zwlekał z tym zadaniem i zaczął zanim Gor Na zlecą nam to zadanie. Odchodząc dodał, że na koniec dnia nie będzie to miało znaczenia czy zostaną Strażnikami, tylko czy będą z tobą wtedy, kiedy to będzie miało znaczenie. Czyżby mieliby być mi potrzebni do jakiegoś zadania, które dostaniemy po ich znalezieniu? | G10: Porada dotycząca jednego z zadań rozdawanych przez MG na grze. | H10: Gor Na Kagan | I10: Strażnicy Świątynni, Nowicjusze | J10: brak | K10: Przybliżenie do awansu na Gor Na
A11: Informacja to podstawa | B11: Grupa | C11: Nie | D11: Siatka szpiegowska | E11: 24 | F11: Trochę czasu już minęło odkąd służę w Faktorii Bractwa, a mimo tego wciąż nie zostałem awansowany do tytułu Gor Na. Wraz z nowoprzybyłymi Strażnikami Świątynnymi niewątpliwie sam będę poddawany próbom przez obecnych w Faktorii Mistrzów. Jeśli nie wykażę się czymś w oczach Gor Na to mogę wiele na tym stracić. Mogą odesłać mnie z powrotem do Obozu na bagnie na ponowne odbycie nauk i treningów pod okiem Cor Angara, a to nie będzie świadczyło dobrze o mnie w oczach Guru. Na szczęście przez cały czas przebywania tutaj zauważyłem jak wartościowe są w oczach Gor Na Kagana informacje. Informacje na których Bractwo może zyskać jeśli podejmie jakieś działania z nimi związane. Wiem, że jeśli wykażę się w tej kwestii to na pewno odróżnię się od pozostałych Gor'ów i tym samym przybliżę moją osobę do wywyższenia na Gor Na. | G11: Porada dotycząca jednego z zadań rozdawanych przez MG na grze. | H11: Gor Na Kagan | I11: Strażnicy Świątynni | J11: brak | K11: Przybliżenie do awansu na Gor Na
A12: Wartość w oczach Bractwa | B12: Grupa | C12: Nie | D12: Zbieranie zasobów | E12: 24 | F12: Po odprawie Cor Angara otrzymałem poradę od Gor Na Draka, który powiedział mi, że próby na Gor Na mają nie tylko sprawdzić naszą sprawność, siłę czy oddanie, ale też zasobność. Powiedział mi, że łatwiej będzie mi zdobyć przchylność mistrzów Straży Świątynnej jeśli w trakcie prób wykażę się umiejętnościami w pozyskiwaniu i dostarczaniu Bractwu magicznych esencji czy komponentów alchemicznych pozyskiwanych z potworów. Gor Na Drak był pewien, że Gor Na Kagan i Guru docenią takie zdolności i zwiększy to moje szanse na zostanie wywyższonym do tytułu Gor Na. | G12: Porada dotycząca jednego z zadań rozdawanych przez MG na grze. | H12: Gor Na Kagan | I12: Strażnicy Świątynni | J12: brak | K12: Przybliżenie do awansu na Gor Na
A13: Nadchodzące negocjacje z Magnatami | B13: Grupa | C13: Tak | D13: Gor Na | E13: 28 | F13: Do Faktorii Bractwa dotarły wieści, że Magnaci zaczynają mieć kłopoty z pełzaczami w Starej Kopalni. Do tego wiemy, że pierwszego dnia Guru mają w planach spotkać się z nimi na rozmowach politycznych. To prawie oczywiste, że Magnaci będą chcieli wykorzystać cenny czas Straży Świątynnej do tego aby wzmocnić bezpieczeństwo kopaczy wydobywających rudę. W naszym interesie jest przypomnieć Guru, że nie mogą zbyt swobodnie dysponować już uszczuplonymi siłami Straży Światynnej. Bractwo musi na tej umowie zyskać naprawdę sporo, żeby było opłacalne. | G13: Porada dla Strażników Świątynnych dotycząca nadchodzących negocjacji Guru z Magnatami. | H13: Gor Na Kagan | I13: Strażnicy Świątynni, Guru, Magnaci | J13: Brak | K13: Pochwała lub opierdol słowny w tym ewentualne reperkusje
... A16: Tęsknota za domem | B16: Postać | C16: Nie | D16: Gor Na Rex | E16: 31 | F16: Sporo czasu minęło odkąd przyjąłem tytuł Gor Na... i mimo tego, że sam przyuczam młodszych braci do tego jakim człowiekiem muszą się stać, aby wiernie służyć Śniącemu to wiem, że sam zboczyłem z tej ścieżki... Mam moje poprzednie życie na sumieniu, o którym nie potrafię zapomnieć. Na domiar złego odnalezienie w tej podłej kolonii karnej ludzi, którzy dzielą mój sentyment tylko odwraca moją uwagę od tego co wiem, że powinno być dla mnie ważniejsze. Widać przywykłem do życia w cierpieniu... i Śniący o tym wie. Odkąd stałem się tak rozdarty Śniący zsyła na mnie koszmary... Koszmary, w których stoję pośród zasp śnieżnych poczas zamieci i walczę z orkami. Z wielkim trudem, jeden za drugim padają od mojego ostrza, ale ich potok nigdy się nie kończy, a ja padam od ich ciosów. Kiedy tak leżę, widzę jak mijają mnie i biegną dalej tam, gdzie nie chcę żeby dobiegli. Kiedy krew moja barwi lód na którym leżę czuję, że jestem sam. Czuję, że nie ma tu nikogo, kto mógłby mi pomóc. Nie ma tu moich Braci, nikogo z rodziny, którą odnalazłem pod Barierą. Wtedy umieram... Poza szokiem i niewyspaniem, które odczuwam po tym nawracającym koszmarze, pojawia się też we mnie uczucie ulgi. Ta ulga to fakt, że budzę się i widzę, że wokół mnie śpią moi Bracia. Wiem, że gdyby byli tam ze mną to nie daliby mi skonać tam na lodowych zaspach... Nie jestem Guru, żeby mieć pewność co wszystko to znaczy i dopóki nie zasięgnę ich rady to mogę się tylko domyślać czego odemnie chce Śniący. Martwię się tylko, że im dłużej waham się co z tym zrobić i im dłużej daję temu trwać... tym gorsze mogą mnie spotkać konsekwencje. (Przez powracające sny z przeszłości jesteś jeszcze bardzier rozdrażniony niż normalnie. Na każdą informację o potencjalnej zdradzie wśród swoich reagujesz wybuchowo. Jedynie rozmowa z innymi skazańcami pochodzącymi z klanów Nordmaru lub rozmowa z kimkolwiek o twojej własnej przeszłości przynosi ci tymczasową ulgę i wracasz do zmysłów [po takiej rozmowie na ok 3 godziny wracają ci zmysły]. Dzieje się tak do momentu kulminacyjnego tego wątku) | G16: Wątek personalny z podsumowania. Początek wątku prowadzącego do sądu Rexa. | H16: Śniący, sentyment do poprzedniego życia, Gor Na Cez | I16: Strażnicy Świątynni, Strażnicy, Guru | J16: Brak | K16: Paliwo do wątków przeciw Rexowi
A17: Wizje… | B17: Postać | C17: Nie | D17: Gor Na Rex | E17: 33 | F17: Nie zbadane są wyroki Śniącego. Co jakiś czas okazywałem się godny, dzięki wiernej służbie i niezachwianej wierze. Zsyłał mi wizje. Jedne proste w interpretacji, inne trudne do zrozumienia nawet dla Baal Ayen. Ostatnio jednak coś się zmieniło. Te wszystkie koszmary senne. Ta jedna jedyna wizja gdy wypalę za dużo... Nordmar... Krew... Krzyki i płacz... Wizje nigdy nie nawiedzały mnie tak często. Nigdy się też nie powtarzały. Ta jedna jednak nawiedza mnie coraz częściej i zawsze tak samo. Orkowie zbiegający ze zbocza gór. Płonąca osada. Śmierć Matki. Sigi wzywająca moje imię z całych sił "Rexxar!". Jej zimne martwe oczy chwilę później... Gdy pierwszy raz, Śniący zesłał mi to wspomnienie jako wizję, od razu omówiłem to z Mistrzynią Ayen. Rozmowa ta przyniosła mi ulgę i spokój. Jednak nie na długo. Wizja wróciła. To jedno przeklęte wspomnienie... Ostatnio wraca do mnie coraz częściej, nawet codziennie. Czy Śniący wystawia mnie na próbę? Oddałbym wszystko by zakończyć te tortury. O co w tym wszystkim chodzi? Nie zbadane są wyroki Śniącego... Do czasu złamania uroku odgrywaj następujący efekt: Przynajmniej raz dziennie (można więcej) odgrywaj, że ponownie przeżywasz wizję której właśnie doświadczyłeś. Podbij odgrywanie negatywnych emocji i szaleństwa. Potem na czas dwóch scen odgrywaj wyczerpanego i zmęczonego. | G17: Wątek opętania Ayen.
A18: Dorwać zaskrońce | B18: Grupa | C18: Tak | D18: SS Kont PL | E18: 25 | F18: Wszystkie kazania Guru na temat węży wśród nas i idące za tym nieudane śledztwa czy urwane tropy zaczynają powoli sprawiać, że nowicjusze zaczynają traktować te tematy jak nieskuteczne straszydło do tego aby zmusić ich do posłuszeństwa i nieufania sobie nawzajem, co powoli zaczyna się stawać prawdą. Groźba ze strony zdrajców w naszej społeczności nie jest brana na poważnie, Nowicjusze zachowują się coraz bardziej swawolnie, a my od miesięcy nie dorwaliśmy nikogo choć wiemy, że tu są. Przez taki obrót spraw Gor Na Cez i Gor Na Kagan stali się napięci jak cięciwa w łuku jeśli tylko ktoś wspomni o tym temacie. Jeszcze chwila i to nas będą winić za taki stan rzeczy. Jeśli szybko nie wyśledzimy przynajmniej kilku z tych zdrajców i nie zaprowadzimy ich przed oblicze sprawiedliwości to nasze życie w Faktorii stanie się istnym koszmarem. | G18: Jest 12 oportunistów z czego 9 to praktycznie węże. Kontynuacja fabuły wewnątrzobozowej. Jakieś tropy warto by im dać. | H18: Gor Na Cez i Gor Na Kagan | I18: Strażnicy Świątynni, Nowicjusze | J18: Brak | K18: Ruda oraz predyspozycje do awansu
A19: Czyste serce to świetlna przyszłość | B19: Grupa | C19: Tak | D19: New Gor PL | E19: 23 | F19: Nauki Cor Angara wyraźnie to mówiły, każdy Nowicjusz podczas mianowania na Strażnika Świątynnego porzuca dawnego siebie i staje się nowym człowiekiem. Jeśli tak się nie stanie to niemożliwe jest by mógł bezgranicznie oddać siebie w służbie Śniącemu. Cor Angar zlecił nam mieć oczy otwarte na naszych własnych braci, a mówili o tym nawet w kontekście, który nie wykluczał Guru, a nawet angażował aspirujących o awans Nowicjuszy. Jeśli zauważymy coś wskazującego na to, że wciaż oglądają się w przeszłość, mamy natychmiast zawiadomić o tym Gor Na przewodzącym Straży Świątynnej w Faktorii, którymi są Gor Na Kagan i Gor Na Cez. Trochę ciężko dziwić się takiemu podejściu, w końcu ciężkie czasy wołają o drastyczne środki... Ale czy to nie za dużo? | G19: Wpis do edycji. Każdy z graczy, również guru, mają mroczną stronę swojej postaci. Należy meldować i prowadzić śledztwo w sprawie każdego podejrzenia. | H19: Cor Angar | I19: Strażnicy Świątynni, Nowicjusze, Guru | J19: brak | K19: Bryłki rudy
A20: Wizje łowcy Wiley'a | B20: Postać | C20: Nie | D20: Gor Toth | E20: 35 | F20: Minęły już prawie trzy miesiące odkąd ostatni raz rozmawiałem z Wiley'em. Jednak ciągle prześladuje mnie myśl, że mogłem zrobić dla niego więcej. Mówił mi wtedy, że ma dziwne sny, czy może nawet przebłyski wizji o Śniącym i o naszym Bractwie... Powinienem go odnaleźć i porozmawiać z nim o tym. Być może Mistrzyni Ayen byłaby w stanie wyczytać w tych snach los, który czeka tego szkodnika. Może to znak, żebym sprowadził go na właściwą ścieżkę? Guru na pewno będą zadowoleni z nowych wyznawców. | G20: Na podstawie karty postaci i podsumowania obu graczy | H20: Wątek na prośbę graczy | I20: Strażnicy Świątynni, Guru, Nowicjusze, Szkodniki | J20: nic | K20: nic
A21: Mistrz i uczeń | B21: Postać | C21: Nie | D21: Gor Na Ragu | E21: 34 | F21: Witara już z nami nie ma. Teraz Gor Tar zajął jego miejsce. Według metod jakie wprowadził Gor Na Kagan powienien zostać oddany pod moje powiernictwo jako uczeń. Obawiam się, że biorąc pod uwagę jak niewielu Gor Na znajduje się obecnie w Faktorii Bractwa, to nie mam co na to liczyć. Mimo tego uważam, że jako jego mistrz, a może i przyjaciel, a za nie długo pewnie i brat, to czuję, że powinienem być dla niego wsparciem w nadchodzącej drodze do jego awansu. Na nas obu czekają wyzwania, to jasne. Dla niego to czas na naukę magii i łowiectwa… Gdyby tego było mało to przez ostatnie wydarzenia nasi Mistrzowie stali się bardzo surowi. Mimo to razem wszystkiemu podołamy. | G21: Kontynuacja wątków z podsumowań na życzenie graczy.
A22: Zawsze stoi mi na drodze | B22: Postać | C22: Nie | D22: Gor Vikr | E22: 35 | F22: Gor Na Rex jest znanym i szanowanym Strażnikiem Świątynnym, a przynajmniej za takiego się uważa. To zwykły uzależniony od ziela wariat, a do tego zaskarbił sobie zaufanie Mistrzów. Jestem przekonany, że nie jest taki święty jak wszystkim się zdaje. Gdybym tylko znalazł jakiegoś haka, informację, może uda mi się podkopać jego autorytet. Rex nigdy nie poprze w głosowaniu mojego awansu... Gdyby stracił w oczach pozostałych Mistrzów to jest szansa, że jego głos zostanie podważony i nie przeszkodzi mi w zostaniu Gor Na. Wiem jedno, nie będę dłużej znosił gróźb i krzyków Rexa. Nadszedł czas zapłaty. | G22: Kontynuacja z podsumowania Vikra, wspólna kosa i niechęć. Rozszerzenie wątku prowadzącego do sądu rexa na grze.
A23: Clear heart is the path to future | B23: Grupa | C23: Tak | D23: New Gor EN | E23: 23 | F23: The teachings of Cor Angar made it clear: every Novice, upon being appointed to the Temple Guard, must abandon their former self and become a new person. If that transformation does not occur, it is impossible for them to wholly dedicate themselves in service to the Sleeper. Cor Angar instructed us to keep our eyes open — even on our own brothers — and this was spoken of in a context that did not exclude the Gurus, even implicating Novices aspiring for promotion. If we notice anything suggesting that someone is still looking back to their past, we are to report it immediately to the Gor Na in charge of the Temple Guards at the Outpost — Gor Na Kagan and Gor Na Cez. It’s hard to blame them for such an approach. After all, desperate times call for drastic measures... But isn't this going too far? | G23: Wpis do edycji. Każdy z graczy, również guru, mają mroczną stronę swojej postaci. Należy meldować i prowadzić śledztwo w sprawie każdego podejrzenia. | H23: Cor Angar | I23: Strażnicy Świątynni, Nowicjusze, Guru | J23: brak | K23: Bryłki rudy
A24: Kolega kopacz potrzebuje pomocy | B24: Postać | C24: Nie | D24: Gor Na Ragu | E24: 36 | F24: Mój znajomy kopacz Maruda ma zawsze coś ciekawego do powiedzenia na temat tego co dzieje się dookoła i nie oczędza w wydawaniu mi esencji magicznych w zamian za rudę, co jest nadwyraz pomocne. Ostatnio jednak miał dla mnie trochę mniej czasu, a wręcz wyglądał na zakłopotanego, gdy rozmawialiśmy pod kopalnią. Powiedział mi, że ma ważną sprawę, którą musi załatwić w związku z innym kopaczem. Nie zastanawiałem się nad tym ani trochę no bo w końcu wszyscy mamy jakieś rzeczy do zrobienia, mniej lub bardziej palące. Jednakże zanim się pożegnalimy zapytał się mnie czy gdyby mnie poprosił o nietypową przysługę, okupioną sowicie rudą czy esencją, to czy chociaż rozważyłbym ją... Wydawał się mocno zakłopotany samym wystosowaniem takiej prośby wobec mnie. Na odchodne powiedziałem mu, że musiałby powiedzieć mi o co chodzi dokładnie i wtedy mógłby się spodziewać mojej odpowiedzi. Maruda wtedy tylko kiwnął głową i w ewidentnym zamyśleniu ruszył w swoim kierunku. Cokolwiek by to nie było, za przysługę tego typu pewnie mogę uzyskać więcej niż rudę czy esencję. Pytanie tylko z jakim ryzykiem wiąże się angażowanie w tą sprawę... A to chyba będę musiał wybadać i ocenić już sam.
A25: Tęsknota, czy wiara | B25: Postać | C25: Nie | D25: Gor Balar | E25: 31 | F25: Minęło już dużo czasu odkąd mnie tutaj zrzucili. Znalazłem tu wszystko czego potrzebowałem. Nowych braci, miejsce do życia, cel. A jednak, mimo wszystko, pojawia się w głowie ta myśl. Rodzina... Dom... Czy żyją? Czy sobie radzą? Kto się teraz nimi opiekuje kiedy mnie zabrakło? Mam nadzieję, że moja siostra Ellie dba dobrze o Ojca. Biedny staruszek nie jest już tak sprawny jak dawniej... Ech, oddałbym wiele, by móc im teraz pomóc. By usłyszeć, że mają się dobrze... Jednak nie może mnie to rozpraszać od moich obecnych obowiązków. Strażnikowi Świątynnemu nie przystoi tęsknić za poprzednim życiem. Stąd i tak nie da się uciec. Jedyna nadzieja w Śniącym... Chyba muszę po prostu o nich zapomnieć... ale... nie chcę. Podczas naszego pierwszego dnia w Faktorii Bractwa ma się odbyć kolejny zrzut skazańców do Kolonii Górniczej. Może powinienem udać się tam i zobaczyć czy nie ma tam jakiś znajomych twarzy. Mógłbym wtedy od kogoś dowiedzieć się jak się sprawy mają poza Barierą. | G25: Jedna ze Skazańczyń jest siostą Balara, Ellie. będzie potrzebowała jego pomocy w trakcie larpa. | H25: Rodzina | I25: Skazańcy, Strażnicy Świątynni | J25: list drugiego dnia, ogarnia Kazik | K25: szczęśliwa rodzina lub Bractwo
A26: Uszy i oczy w Nowym Obozie | B26: Postać | C26: Nie | D26: Gor Gyyrax | E26: 35 | F26: Słyszałem, że w okolicach Faktorii informacje bywają często cenniejsze niż ruda. Nie zamierzam więc przybyć tam nieprzygotowany. Jeden z nowicjuszy, Zysk, ma sporo kontaktów w Nowym Obozie, a to może się okazać bardzo przydatne. Zgodził się, za niewielką zapłatą, szpiegować i donosić mi o wszystkim czego się dowie. Muszę dopilnować, żeby te informacje trafiały bezpośrednio do mnie. Jeśli dostarczę moim Mistrzom dość wiadomości to zaskarbię sobie ich zaufanie, a to z pewnością przybliży mnie do awansu. | G26: jest drugi koniec u Zyska | H26: SŚ | I26: Strażnicy Świątynni, Nowicjusze | J26: nic | K26: nic
A27: Wczorajsza wizja | B27: Postać | C27: Nie | D27: Gor Na Ragu | E27: 32 | F27: Na dzień przed wyruszeniem do Faktorii Bractwa, udałeś się do świątyni Śniącego aby zebrać myśli. Było tam dość pusto, pojedynczy Nowicjusze kończyli właśnie ostatnie porządki. Wsłuchując się w ciszę i aurę tego miejsca pogrążyłeś się w modlitwie. Wtedy to ujrzałeś. Silbach. Stałeś w samym środku wioski. Ludzie dookoła świętowali, bawili się. Na uboczu zobaczyłeś pewną postać. Kobietę odtrąconą przez tłum. Spotkaliście się wzrokiem. Była smutna, a jej oczy szukały ratunku. Czułeś jak na Twojej twarzy maluje się współczucie i zrozumienie. Uśmiechnęła się lekko, a jej oczy wypełniła nadzieja. Nagle wszystko się rozpłynęło, a gdy otworzyłeś oczy znów byłeś w świątyni. "Wizja" pomyślałeś... Miałeś wrażenie, że znasz tę dziewczynę. "Digis", chyba tak miała na imię, była miejscową zielarką. "Ale co to ma wspólnego ze mną?". Myślałeś przez chwilę, ale nie znalazłeś na to pytanie odpowiedzi. Zmęczony i zamyślony postanowiłeś udać się na spoczynek. Jutro w końcu wielki dzień przybycia wiernych z Obozu Bractwa do Faktorii... i zrzutu nowych skazańców do kolonii... | G27: Wątek o silbach na próbę gracza, Digis będzie potrzebować pomocy Ragu | H27: Los, Gor Na Cez | I27: Skazańcy, Strażnicy Świątynni | J27: brak | K27: Nowy członek dla bractwa
A28: Niewierni przyjaciele moich braci | B28: Postać | C28: Nie | D28: Gor Ruh | E28: 35 | F28: Słyszałem od Gor Na wracających z Faktorii Bractwa, że niektórzy spośród Strażników Świątynnych przebywających w Faktorii Bractwa, utrzymają bardziej niż przyjazne kontakty z niewiernymi. Zwłaszcza ze Strażnikami ze Starego Obozu. W świetle tego co słyszałem o doktrynach jakie przekazują Gor na Kagan i Gor Na Cez to moim obowiązkiem jest informowanie ich o tym. Wystarczy tylko, że usłyszę lub zobaczę na własne oczy jak i z kim te relacje wyglądają, a na pewno zostanę za te doniesienia wynagrodzony. | G28: Wątek na podstawie kp, pierwszy larp. Może się połączyć z wątkami o wewnętrznych konfliktach SŚ i sądzie Rexa. Zredagowane, przepisane. Do tego zachacza o poczucie obowiązku, które gracz zapisał w karcie postaci.
A29: Enemies from the past | B29: Postać | C29: Nie | D29: Gor Bács | E29: 39 | F29: I still can't forget how Shadows and Guard from Old Camp treated me when I was a newbie convict freshly thrown to the Colony. My guess is that besides that they didn't like my face they could not understand my language.. Thou I speak Old Myrthanian only it's just unforgivable that they had almost killed me. I know, I became a new man when I was taken into Temple Guard caste, but this cannot continue, not with those two.. A lot of days have past since then and I still remember their names.. Torin and Deavon.. Yet, I am torn apart between decisions. How should I retaliate so they won't do any of that again.. or should I make peace with them? Either way I must do something about it. | G29: Po wrzuceniu do koloni został dotkliwie pobity przez dwóch cieni, teraz do niego należy decyzja czy wybierze zemstę, czy pojednanie | H29: nic | I29: Strażnicy Świątynni, Cienie | J29: nic | K29: nic
A30: Kto zadziera z Bractwem | B30: Grupa | C30: Tak | D30: SS Kont PL | E30: 26 | F30: Doszły was słuchy, że Nowicjusze notorycznie narzekają pomiędzy sobą i ostrzegają się nawzajem przed jednym Cieniem, który ma na sumieniu poważne występki przeciwko sługom Śniącego. Ponoć bez opamiętania wybiera sobie to nieporadniejszych Nowicjuszy na cel, kradnie od nich skręty bagiennego ziela oraz rudę, a tym samym urąga reputacji Bractwa jako społeczności, która chroni swoich wiernych. Pora przerwać ten proceder. Ponoć Nowicjusz Arno został przez niego osobiście napadnięty i pewnie chętnie nam go wskaże. Problem tylko jest taki, że kilka oskażeń nie wystarczy, bo Gomez i jego Strażnicy dobrze chronią swoich ludzi... Trzeba będzie tego gagatka przyłapać na kolejnym występku i dopiero wtedy działać. | G30: Marko pogrywa sobie z bractwem, napada nowicjuszy, kradnie bagienne ziele i czerpie z tego korzyści. Pora przerwać ten proceder. (wpisać nowicjuszom cienia Marko w wątkach jako tego, który na nich napada. Status: Napisane Mortisowi żeby zrobił Marko wpis po swojej stronie, Mortis przekazał kwestię Lisowi) Wpisać Arno wątek, że pamieta dobrze mordę tego gościa i jego imię. Oraz, że czas z tym pójść do straży i odegrać się należycie | H30: Gor Na Kagan, Gor Na Cez | I30: Strażnicy Świątynni, Nowicjusze, Cienie | J30: brak | K30: ruda, pochwała, przybliżenie do awansu na Gor Na
A31: Inni mówią, że to rupieć. Ja nazywam to skarbem. | B31: Postać | C31: Nie | D31: Gor Tar | E31: 34 | F31: Myślałeś, że los się do ciebie uśmiechnął. Znalazłeś przy zwłokach jakiegoś nieszczęśnika rozszarpanego przez dzikie bestie fragment listu. Kiedy otworzyłeś go, nie wiedziałeś czego się spodziewać, ale na pewno nie takiego bełkotu o magach, teleportach, klielichach i innych fantasmagoriach. Do tego jakiś zwój magiczny, ale równie bezużyteczny - pytałeś już o to Guru. Nie wygląda na to, żeby miał ci się na coś przydać i już miałeś go wyrzucić, ale... Pomyślałeś sobie, że jeśli miał go przy sobie jakiś obdartus to prawdopodobnie ukradł go od kogoś wpływowego. Kto wie? Może znajdzie się ktoś, kto zapłaci okrągłą sumkę za taki świstek? | G31: quest od Keiry - ma fragment listu prowadzący do zgonu Maginii Wiktorii - list ogarnia Keira | H31: Keira | I31: Strażnicy Świątynni, Magowie Wody | J31: https://docs.google.com/document/d/15m2ZdaJyBUS_MzACpZqPqOgolPGrQzCR1-YrHf0lGRU/edit?tab=t.0 | K31: <- list do druku ogarnia Keira
A32: Tchnienie braci moich | B32: Postać | C32: Nie | D32: Gor Tar | E32: 32 | F32: Pamiętasz dobrze moment w którym Baal Sach położył swoją rękę na twojej głowie i powiedział, że staniesz się Gor Na. W tamtym momencie wiedziałeś, że to prawda ponieważ przez dotyk czułeś przepływające Tchnienie. Nie dało się tego pomylić z niczym innym. Czułeś jak Śniący przemawia przez proroka. Podczas ostatnich wielu dni treningów wśród Straży Świątynnej w obozie Bractwa nie raz śniłeś o tamtej wspaniałej chwili. A jednak kiedy we śnie rozglądasz się pośród braci, którzy byli tam wtedy z tobą widzisz jak przez wielu z nich to Tchnienie przepływa. U jednych swobodnie, z mniejszym lub większym natężeniem, a u innych stłamszone, rozdarte i niejednostajne. Jesteś pewien, że coś z nimi jest nie tak, w jednym momencie patrzą na ciebie i uczestniczą w modlitwie wiernych, a w drugiej odwracają się i oglądają wstecz, patrząc daleko w tył. Wśród tych zagłuszonych duchów znajduje się Gor Na Ragu, Gor Na Rex... i wiele innych znajomych sylwetek. Choć nie widzisz ich twarzy, wiesz że to oni, a widok ten sprawia ci ból, który dobrze znasz, choćby z twoich dni bycia Nowicjuszem. Rankiem, po nocy, w której miewasz ten sen, zawsze czujesz ulgę, ale nie wiesz czemu. W końcu widok stłamszonych duchów braci, których uważasz za wzory powoduje ci tyle cierpienia... Jesteś pewien co do jednego. To znak od Śniącego, że musisz im pomóc oddać się Śniącemu całkowicie. Wiesz, że masz dar, z którego nie potrafisz jeszcze korzystać, ale który ma realny wpływ na twoje życie... Dar od Śniącego. Kiedy przebywałeś w Obozie Bractwa wśród nowych Gor'ów takich jak ty krążyło wiele plotek na temat Gor Na przebywających w Faktorii... Podobno jeden z nich, dawno temu, odprawił z Guru rytuał, za pomocą którego stał się "natchniony przez samego Śniącego". Rzekome błogosławieństwo miało objawiać się w jego oczach raz po raz i dzięki niemu miał widzieć więcej niż pozostali bracia... Nie mogę oprzeć się wrażeniu, że brzmi to bardzo podobnie do tego co ze mną się dzieje... Tylko, który z Guru mógłby pamietać tamte czasy i który z Gor Na był tym błogosławionym. Mam swoje podejrzenia, ale prawdy nie dowiem się jeśli nie będę za nią aktywnie podążał... | G32: Wątek "Tchnienia" Gor Tara, który naprowadza go na nieczyste dusze znajdujące się pośród SŚ. Wątek będzie kontynuowany przez sprowadzanie wizji na Gor Tara w obecności Baal'a Mosira i Gor Na Kagana (może jeszcze Ayen, bo jest od wizji). Będzie za pomocą tego w stanie wyszukiwać zdrajców w obozie i uzyskiwać informacje na temat rzeczy ukrytych przed wzrokiem. | H32: Śniący | I32: Strażnicy Świątynni | J32: nic | K32: nic
A33: Dawny znajomy | B33: Postać | C33: Nie | D33: Gor Na Rex | E33: 37 | F33: Na dzień przed wyruszeniem do Faktorii, Gor Na Cez wspomniał, że ma pewną sprawę o której mi opowie jak dotrzemy na miejsce. Podobno chodzi o naszego dawnego przyjaciela. Nie chciał mi powiedzieć niestety nic więcej... Ciekawe o co chodzi. | G33: Zahaczka żeby wciągnąć Rexa do exhumacji Kennetha | H33: Gor Na Cez | I33: Strażnicy Świątynni, Guru, Nowicjusze | J33: kukła Kennetha, moderowana scena exhumacji. (zgłoszone organizacji) | K33: Ostatnia przygoda z Kennethem.
A34: Artefakt dla bractwa | B34: Postać | C34: Nie | D34: Gor Na Rex | E34: 35 | F34: Kolonia Górnicza to małe miejsce. Wieści i plotki szybko się roznoszą, a najciekawsze informacje docierają nawet do nas na bagno. Pewien Nowicjusz doniósł mi, że Garhax, Strażnik którego z resztą dobrze znam, wszedł w posiadanie pewnego przedmiotu. Jest to podobno nowa broń. Ostrze o magicznej mocy. Czy to możliwe żeby zwykły Strażnik zdobył sam coś takiego? A magiczne właściwości tego ostrza? Taki artefakt nie powinien się znajdować w rękach Starego Obozu. Muszę porozmawiać z Garhaxem i dowiedzieć się czegoś więcej. Baalowie na pewno chętnie usłyszą o tych magicznych właściwościach, a przysłużę się jeszcze bardziej jeśli sprawię, że to ostrze będzie służyło Bractwu. Ta broń musi trafić przed oblicze Guru. Taki artefakt musi zostać przez nich zbadany. Dopilnuję tego. | G34: Wątek personalny Garhaxa | H34: Fanatyzm | I34: Strażnicy, Strażnicy Świątynni | J34: Miecz Garhaxa (ogarnia gracz) | K34: Uznanie Guru, możliwy nowy członek dla Bractwa
A35: To wizje? Koszmary? Czy może wspomnienia? | B35: Postać | C35: Nie | D35: Gor Vith | E35: 35 | F35: Śniący okazjonalnie zsyła mi różne wizje. Jednak ostatnio widzę je częściej, dokładniej jedną. Jesteśmy w środku napadu, rabujemy zwykły transport narzędzi na głównym trakcie między miastami. Gdy są wystarczająco blisko wyskakuję z ukrycia i zadaję pierwsze ciosy. Gdy członkowie karawany padają na ziemię, widzę ich zakrwawione twarze i zimne pobielałe oczy. Podnoszę wzrok i przeszywa mnie dreszcz. Przede mną stoją tłumy. Zapłakane żony ofiar, całe rodziny. Nie mogę się ruszyć. Z bezruchu wyrywa mnie dopiero uderzenie strażnika miejskiego, który z całym oddziałem łapie mnie i morduje moich towarzyszy. Wleczony do więzienia tracę przytomność. Budzę się znowu w kolonii. Nie mam pojęcia czemu ta wizja tak często mnie teraz nawiedza. Gdy pojawiła się po raz pierwszy poszedłem porozmawiać z Baal Ayen, naszą Mistrzynią. Jednak wizja zaczęła wracać do mnie coraz częściej. Nie pamiętam bym miał choć dzień wytchnienia... Co to wszystko znaczy? Czy Śniący chce mi coś przekazać? Do czasu złamania uroku odgrywaj następujący efekt: Przynajmniej raz dziennie (można więcej) odgrywaj, że ponownie przeżywasz wizję której właśnie doświadczyłeś. Podbij odgrywanie negatywnych emocji i szaleństwa. Potem na czas dwóch scen odgrywaj wyczerpanego i zmęczonego.
A36: Ruda za moje oddanie | B36: Grupa | C36: Nie | D36: SS PL | E36: 29 | F36: Magiczna ruda... krew w żyłach organizmu jakim jest Górnicza Dolina zamknięta pod Barierą. Za wypełnianie obowiązków Straży Świątynnej mogę zgosić się każdego poranka do Gor Na Kagana lub Gor Na Ceza, aby odebrać Trybut. Dla Gor jest to 15 bryłek, dla Gor Na — 30... Za udział w zbrojnych zadaniach, na których narażamy nasze życia, również otrzymuję zapłatę, Gor otrzymują 20, z kolei Gor Na — 40 za każdą taką misję. Oczywiście, wypełniając zadania Gor Na ponad te wymagające zbrojnej ręki, otrzymujemy nagrodę, ale tu jej wysokość zależy od tego jak trudne są i od kosztu ich realizacji. Dla szukających kolejnego pewnego źródła rudy są jeszcze Guru, którym i tak już służymy, ale żeby zostać przez nich obdarowanym trzeba czuwać przy nich dzień i noc, a co za tym idzie, zrezygnować z innch zadań. No, ale to już do mnie należy decyzja jakim sprawom w ciągu dnia się oddam. | G36: Wątek informujący o źródłach finansowania SŚ | H36: Gor Na Kagan, Gor Na Cez | I36: Strażnicy Świątynni, Guru | J36: ruda od Karola | K36: ruda
A37: Ore for my devotion | B37: Grupa | C37: Nie | D37: SS EN | E37: 29 | F37: Magic ore… the blood coursing through the veins of the organism that is the Valley of Mines, sealed beneath the Barrier. For fulfilling the duties of the Temple Guard, I can report every morning to Gor Na Kagan or Gor Na Cez to receive my Tribute. For a Gor, it's 15 ore, for a Gor Na — 30... For participating in armed missions, where we risk our lives, I also receive payment — 20 for a Gor, and 40 for a Gor Na per mission. Of course, when carrying out tasks from the Gor Na beyond those that require a strong arm, we receive a reward as well, but its amount depends on how difficult the task is and how costly it is to complete. For those seeking another steady source of ore, there are also the Gurus — whom we already serve — but to be granted their favor, one must remain by their side day and night. And that means giving up other duties. Well, in the end, it’s up to me to decide which matters I take upon myself each day. | G37: Wątek informujący o źródłach finansowania SŚ | H37: Gor Na Kagan, Gor Na Cez | I37: Strażnicy Świątynni, Guru | J37: ruda od Karola | K37: ruda
A38: Niech Śniący ma mnie w swojej opiece | B38: Grupa | C38: Nie | D38: SS Kont Gor PL | E38: 22 | F38: Jestem Strażnikiem Świątynnym od dłuższego czasu, a mimo to wciąż nie udało mi się otrzymać tytułu Gor Na. Nie pamiętam już, czy stało się tak przez to, że za mało się starałem, czy przez to, że zająłem się zadaniami, które w oczach tamtych Gor Na były mniej wartościowe... W każdym razie, od pewnego czasu Gor Na Kagan patrzy na ten stan rzeczy podejrzliwym wzrokiem. Na początku, od czasu do czasu, wyrażał zdziwienie, że pomimo tak długiej służby wciąż ktoś mnie w tym awansie ubiega... Mówił, że jeszcze przyjdzie na mnie pora lub że wobec kogoś Śniący był szczodrzejszy... Ostatnio w jego głosie pojawiło się wyraźne zirytowanie, kiedy o tym mówił, a potem – podejrzliwość w oczach... Widzę to jasno – ma wobec mnie pewne oczekiwania i jeśli ich nie spełnię, nie pokażę, że naprawdę się staram, że to wszystko jest złe fatum, to mogę stracić coś więcej niż moją pozycję w Bractwie... | G38: Wątek zapalający ognisko pod dupą Gora z kontynuacją | H38: Gor Na Kagan | I38: Strażnicy Świątynni | J38: nóż | K38: zachowanie życia
A39: May the Sleeper watch over me | B39: Grupa | C39: Nie | D39: SS Kont Gor EN | E39: 22 | F39: I’ve been a Temple Guard for quite some time now, and yet I still haven’t managed to earn the title of Gor Na. I can no longer remember whether it’s because I didn’t try hard enough, or because I took on tasks that, in the eyes of those Gor Na, were of lesser value... In any case, for some time now, Gor Na Kagan has been eyeing this situation with suspicion. At first, from time to time, he would express surprise that despite such long service, someone else always manages to outrun me in promotion... He said my time would come, or that the Sleeper had been more generous to someone else... Lately, there's been clear irritation in his voice when he speaks of it — and then, suspicion in his eyes... I see it clearly now — he has certain expectations of me, and if I don’t meet them, if I don’t prove that I’m truly making an effort, that it’s all just a matter of cruel fate, then I may lose something more than just my position within the Brotherhood... | G39: Wątek zapalający ognisko pod dupą Gora z kontynuacją | H39: Gor Na Kagan | I39: Strażnicy Świątynni | J39: nóż | K39: zachowanie życia
A40: Problems of my people | B40: Postać | C40: Nie | D40: Gor Omba | E40: 35 | F40: I recently heard that my Temple Guard brothers have come in contact with swamp weed smokes which were manufactured in the New Camp rice field outpost... I'm sure that they'll use whatever means nessesary to find and shut down this business that harms brotherhood main source of ore. I should try to outrun them and use my contacts in there and take this matter into my hands. If I manage to do so I'll certainly prove myself useful to the rest of the Temple Guards and thus take some heat off my shoulders.
A41: They are not faithful enought | B41: Postać | C41: Nie | D41: Gor Gior | E41: 35 | F41: I know for a fact that Novices duties in the Brotherhood Outpost are mainly conected to dealing swamp weed. Which is fine and I have no problem with that. But besides that and taking part in obligatory ceremonies organized by Gurus it is not enough in my book... I should encourage them to pray more and show their devotion to the Sleeper. They should be thankful that they are part of this wonderful religion and I'll help them prove it to us. I should set up designated offering station in the Brotherhood Outpost and look closely which of them make offes and which do not. Information about that will certainly be useful to Gurus and moreover that ore coming from offerings will most definitaly help our Temple Guard missions.
A42: Since I am doing mostly guard duties | B42: Postać | C42: Nie | D42: Gor Omba | E42: 33 | F42: Since I am doing mostly guard duties I should use that to my advantage. Discipline among Novices is a thing that Gor Na Kagan speaks oftenly from some time now. I know for a fact what he means by that: I ought to keep peace and silence in the Brotherhood Outpost to make this place proper for meditation, I should watch over Novices so they don't steal either from each other as well as watch over any incoming guests. So there's that. No stealing, no screaming and making ruckus. Maybe if I add to this organisation of fighting lessons for other Temple Guards and Novices I'll make myself even more useful. Gor Na will certainly notice my deviotion if manage to pull this off.
...

Sheet Data_Validation
